Workbook

Sheet How to use
A1: Three-statement forecast
A2: The GM's Ledger course template. Example figures are for BraceWorks Medical, a fictional company: replace them with your own.
A4: What it's for
A5: A linked three-year forecast of the income statement, balance sheet and cash flow, with the overdraft as the balancing item, covenant tests and a balance check (Module 22).
A7: How to use it
A8: 1. On the Assumptions sheet, type your opening balance sheet from last year's accounts. The opening balance check must read zero.
A9: 2. Set the drivers for each year: growth, margin, cost increases, customer, stock and supplier days, equipment, loans and dividends.
A10: 3. Check the fixed rules: interest rate, tax rate, minimum cash, overdraft limit and covenant.
A11: 4. Open the Forecast sheet. The balance check must read zero; the status row shows whether a limit is breached.
A12: 5. Save a copy, then change a few drivers for a downside case and compare. Know what breaks first.
A14: Colour legend
A15: Blue text on yellow: an input. Type your own figures here.
... A17: Green text: a figure brought in from another sheet.

Sheet Assumptions
A1: Three-statement forecast: assumptions
A2: US dollars. Change only the yellow cells. Example: BraceWorks Medical (fictional), opening from its 31 December balance sheet (Module 1).
A4: Driver | B4: Year 1 | C4: Year 2 | D4: Year 3 | E4: Note
A5: Sales growth | B5: 0.05 | C5: 0.05 | D5: 0.05 | E5: Module 15
A6: Gross margin before depreciation | B6: 0.315 | C6: 0.315 | D6: 0.315 | E6: Last year: $378,000 ÷ $1,200,000
A7: Selling and admin cost increase | B7: 0.04 | C7: 0.04 | D7: 0.04 | E7: Wages and inflation
A8: Customer days (DSO) | B8: 70 | C8: 70 | D8: 70 | E8: Module 16
A9: Stock days (of cost of sales incl. depreciation) | B9: 106 | C9: 106 | D9: 106 | E9: Module 7
A10: Supplier days (of materials) | B10: 63 | C10: 63 | D10: 63 | E10: Module 16
A11: Materials as % of revenue | B11: 0.46 | C11: 0.46 | D11: 0.46 | E11: For supplier days
A12: Equipment purchases | B12: 60000 | C12: 30000 | D12: 30000 | E12: Module 14
A13: New equipment loan | B13: 0 | C13: 0 | D13: 0 | E13: Module 20
A14: Loan repayments | B14: 20000 | C14: 20000 | D14: 20000 | E14: Loan schedule
A15: Dividends | B15: 0 | C15: 20000 | D15: 20000 | E15: Module 20
A17: Fixed rules
A18: Interest rate on overdraft and loans | B18: 0.064 | E18: Charged on opening balances, plus half a year on new loans
A19: Tax rate | B19: 0.25 | E19: Example rate: see Module 19 for your country
A20: Useful life of new equipment (years) | B20: 8 | E20: Half a year of depreciation in the year bought
A21: Depreciation on existing equipment, per year | B21: 38000 | E21: Last year's charge
A22: Minimum cash balance | B22: 20000 | E22: The overdraft covers any shortfall below this
A23: Overdraft limit | B23: 150000 | E23: From the bank facility letter
A24: Covenant: net debt ÷ EBITDA no more than | B24: 2.5 | E24: From the loan agreement
A26: Last year and opening balance sheet (31 December)
A27: Revenue last year | B27: 1200000
A28: Selling and admin last year | B28: 246000
A29: Cash | B29: 42000
A30: Receivables | B30: 230000
A31: Inventory | B31: 250000
A32: Prepayments | B32: 13000
A33: Equipment, net | B33: 310000
A34: Payables | B34: 95000
A35: Accrued expenses | B35: 30000
A36: Tax payable | B36: 8500
A37: Overdraft | B37: 120000
A38: Equipment loan | B38: 100000
... A40: Retained earnings | B40: 241500
A41: Opening balance check (must be zero) | B41: =SUM(B29:B33)-SUM(B34:B40) -> 0

Sheet Forecast
A1: Three-statement forecast
A2: US dollars. All formulas: change the Assumptions sheet, not this one. Negative numbers in brackets.
B4: Last year / opening | C4: Year 1 | D4: Year 2 | E4: Year 3
A5: Income statement
A6: Revenue | B6: =Assumptions!B27 -> 1200000 | C6: =B6*(1+Assumptions!B5) -> 1260000 | D6: =C6*(1+Assumptions!C5) -> 1323000 | E6: =D6*(1+Assumptions!D5) -> 1389150
A7: Cost of sales (excl. depreciation) | C7: =-C6*(1-Assumptions!B6) -> -863100 | D7: =-D6*(1-Assumptions!C6) -> -906255 | E7: =-E6*(1-Assumptions!D6) -> -951567.75
A8: Selling and admin | B8: =-Assumptions!B28 -> -246000 | C8: =-Assumptions!B28*(1+Assumptions!B7) -> -255840 | D8: =C8*(1+Assumptions!C7) -> -266073.6 | E8: =D8*(1+Assumptions!D7) -> -276716.54
A9: EBITDA | C9: =C6+C7+C8 -> 141060 | D9: =D6+D7+D8 -> 150671.4 | E9: =E6+E7+E8 -> 160865.71
A10: Depreciation | C10: =-(Assumptions!$B$21+Assumptions!B12/(2*Assumptions!$B$20)) -> -41750 | D10: =-(Assumptions!$B$21+Assumptions!B12/Assumptions!$B$20+Assumptions!C12/(2*Assumptions!$B$20)) -> -47375 | E10: =-(Assumptions!$B$21+(Assumptions!B12+Assumptions!C12)/Assumptions!$B$20+Assumptions!D12/(2*Assumptions!$B$20)) -> -51125
A11: Operating profit | C11: =C9+C10 -> 99310 | D11: =D9+D10 -> 103296.4 | E11: =E9+E10 -> 109740.71
A12: Interest | C12: =-Assumptions!$B$18*(B27+B28+Assumptions!B13/2) -> -14080 | D12: =-Assumptions!$B$18*(C27+C28+Assumptions!C13/2) -> -10989.385 | E12: =-Assumptions!$B$18*(D27+D28+Assumptions!D13/2) -> -8086.4188
A13: Profit before tax | C13: =C11+C12 -> 85230 | D13: =D11+D12 -> 92307.015 | E13: =E11+E12 -> 101654.29
A14: Tax | C14: =-MAX(0,C13)*Assumptions!$B$19 -> -21307.5 | D14: =-MAX(0,D13)*Assumptions!$B$19 -> -23076.754 | E14: =-MAX(0,E13)*Assumptions!$B$19 -> -25413.572
A15: Net profit | C15: =C13+C14 -> 63922.5 | D15: =D13+D14 -> 69230.261 | E15: =E13+E14 -> 76240.715
A17: Balance sheet, 31 December
A18: Cash | B18: =Assumptions!B29 -> 42000 | C18: =C47 -> 20000 | D18: =D47 -> 20000 | E18: =E47 -> 20000
A19: Receivables | B19: =Assumptions!B30 -> 230000 | C19: =C6*Assumptions!B8/365 -> 241643.84 | D19: =D6*Assumptions!C8/365 -> 253726.03 | E19: =E6*Assumptions!D8/365 -> 266412.33
A20: Inventory | B20: =Assumptions!B31 -> 250000 | C20: =-(C7+C10)*Assumptions!B9/365 -> 262778.36 | D20: =-(D7+D10)*Assumptions!C9/365 -> 276944.6 | E20: =-(E7+E10)*Assumptions!D9/365 -> 291192.96
A21: Prepayments | B21: =Assumptions!B32 -> 13000 | C21: =B21 -> 13000 | D21: =C21 -> 13000 | E21: =D21 -> 13000
A22: Equipment, net | B22: =Assumptions!B33 -> 310000 | C22: =B22+Assumptions!B12+C10 -> 328250 | D22: =C22+Assumptions!C12+D10 -> 310875 | E22: =D22+Assumptions!D12+E10 -> 289750
A23: Total assets | B23: =SUM(B18:B22) -> 845000 | C23: =SUM(C18:C22) -> 865672.19 | D23: =SUM(D18:D22) -> 874545.63 | E23: =SUM(E18:E22) -> 880355.29
A24: Payables | B24: =Assumptions!B34 -> 95000 | C24: =C6*Assumptions!B11*Assumptions!B10/365 -> 100040.55 | D24: =D6*Assumptions!C11*Assumptions!C10/365 -> 105042.58 | E24: =E6*Assumptions!D11*Assumptions!D10/365 -> 110294.7
A25: Accrued expenses | B25: =Assumptions!B35 -> 30000 | C25: =B25 -> 30000 | D25: =C25 -> 30000 | E25: =D25 -> 30000
A26: Tax payable | B26: =Assumptions!B36 -> 8500 | C26: =B26 -> 8500 | D26: =C26 -> 8500 | E26: =D26 -> 8500
A27: Overdraft | B27: =Assumptions!B37 -> 120000 | C27: =B27+C46 -> 91709.144 | D27: =C27+D46 -> 66350.294 | E27: =D27+E46 -> 30667.111
A28: Equipment loan | B28: =Assumptions!B38 -> 100000 | C28: =B28-MIN(Assumptions!B14,B28)+Assumptions!B13 -> 80000 | D28: =C28-MIN(Assumptions!C14,C28)+Assumptions!C13 -> 60000 | E28: =D28-MIN(Assumptions!D14,D28)+Assumptions!D13 -> 40000
A29: Share capital | B29: =Assumptions!B39 -> 250000 | C29: =B29 -> 250000 | D29: =C29 -> 250000 | E29: =D29 -> 250000
A30: Retained earnings | B30: =Assumptions!B40 -> 241500 | C30: =B30+C15-Assumptions!B15 -> 305422.5 | D30: =C30+D15-Assumptions!C15 -> 354652.76 | E30: =D30+E15-Assumptions!D15 -> 410893.48
A31: Total liabilities and equity | B31: =SUM(B24:B30) -> 845000 | C31: =SUM(C24:C30) -> 865672.19 | D31: =SUM(D24:D30) -> 874545.63 | E31: =SUM(E24:E30) -> 880355.29
A33: Cash flow statement
A34: Net profit | C34: =C15 -> 63922.5 | D34: =D15 -> 69230.261 | E34: =E15 -> 76240.715
A35: Add back depreciation | C35: =-C10 -> 41750 | D35: =-D10 -> 47375 | E35: =-E10 -> 51125
A36: Receivables (increase) / decrease | C36: =B19-C19 -> -11643.836 | D36: =C19-D19 -> -12082.192 | E36: =D19-E19 -> -12686.301
A37: Inventory (increase) / decrease | C37: =B20-C20 -> -12778.356 | D37: =C20-D20 -> -14166.247 | E37: =D20-E20 -> -14248.36
A38: Payables increase / (decrease) | C38: =C24-B24 -> 5040.5479 | D38: =D24-C24 -> 5002.0274 | E38: =E24-D24 -> 5252.1288
A39: Cash from operations | C39: =SUM(C34:C38) -> 86290.856 | D39: =SUM(D34:D38) -> 95358.85 | E39: =SUM(E34:E38) -> 105683.18
A40: Equipment purchases | C40: =-Assumptions!B12 -> -60000 | D40: =-Assumptions!C12 -> -30000 | E40: =-Assumptions!D12 -> -30000
A41: Free cash flow | C41: =C39+C40 -> 26290.856 | D41: =D39+D40 -> 65358.85 | E41: =E39+E40 -> 75683.183
A42: Loan repayments | C42: =-MIN(Assumptions!B14,B28) -> -20000 | D42: =-MIN(Assumptions!C14,C28) -> -20000 | E42: =-MIN(Assumptions!D14,D28) -> -20000
A43: New equipment loan | C43: =Assumptions!B13 -> 0 | D43: =Assumptions!C13 -> 0 | E43: =Assumptions!D13 -> 0
...
